<?xml version="1.0" encoding="utf-8"?>
<!-- Same a gym ant but with gear ratio of 30 and sites -->
<mujoco model="ant">
    <body name="invis_torso" pos="-3 -3 0.75">
      <geom name="invis_torso_geom" pos="0 0 0" size="0.25" type="sphere" rgba="0.9 0.7 0.7 0.2" contype="1" conaffinity="0"/>
      <joint armature="0" damping="0" limited="false" margin="0.01" name="invis_root" pos="0 0 0" type="free"/>
      <body name="invis_front_left_leg" pos="0 0 0">
        <geom fromto="0.0 0.0 0.0 0.2 0.2 0.0" name="invis_aux_1_geom" size="0.08" type="capsule" rgba="0.9 0.7 0.7 0.2" contype="1" conaffinity="0"/>
        <body name="invis_aux_1" pos="0.2 0.2 0">
          <joint axis="0 0 1" name="invis_hip_1" pos="0.0 0.0 0.0" range="-30 30" type="hinge"/>
          <geom fromto="0.0 0.0 0.0 0.2 0.2 0.0" name="invis_left_leg_geom" size="0.08" type="capsule" rgba="0.9 0.7 0.7 0.2" contype="1" conaffinity="0"/>
          <body pos="0.2 0.2 0">
            <joint axis="-1 1 0" name="invis_ankle_1" pos="0.0 0.0 0.0" range="30 70" type="hinge"/>
            <geom fromto="0.0 0.0 0.0 0.4 0.4 0.0" name="invis_left_ankle_geom" size="0.08" type="capsule" rgba="0.9 0.7 0.7 0.2" contype="1" conaffinity="0"/>
          </body>
        </body>
      </body>
      <body name="invis_front_right_leg" pos="0 0 0">
        <geom fromto="0.0 0.0 0.0 -0.2 0.2 0.0" name="invis_aux_2_geom" size="0.08" type="capsule" rgba="0.9 0.7 0.7 0.2" contype="1" conaffinity="0"/>
        <body name="invis_aux_2" pos="-0.2 0.2 0">
          <joint axis="0 0 1" name="invis_hip_2" pos="0.0 0.0 0.0" range="-30 30" type="hinge"/>
          <geom fromto="0.0 0.0 0.0 -0.2 0.2 0.0" name="invis_right_leg_geom" size="0.08" type="capsule" rgba="0.9 0.7 0.7 0.2" contype="1" conaffinity="0"/>
          <body pos="-0.2 0.2 0">
            <joint axis="1 1 0" name="invis_ankle_2" pos="0.0 0.0 0.0" range="-70 -30" type="hinge"/>
            <geom fromto="0.0 0.0 0.0 -0.4 0.4 0.0" name="invis_right_ankle_geom" size="0.08" type="capsule" rgba="0.9 0.7 0.7 0.2" contype="1" conaffinity="0"/>
          </body>
        </body>
      </body>
      <body name="invis_back_leg" pos="0 0 0">
        <geom fromto="0.0 0.0 0.0 -0.2 -0.2 0.0" name="invis_aux_3_geom" size="0.08" type="capsule" rgba="0.9 0.7 0.7 0.2" contype="1" conaffinity="0"/>
        <body name="invis_aux_3" pos="-0.2 -0.2 0">
          <joint axis="0 0 1" name="invis_hip_3" pos="0.0 0.0 0.0" range="-30 30" type="hinge"/>
          <geom fromto="0.0 0.0 0.0 -0.2 -0.2 0.0" name="invis_back_leg_geom" size="0.08" type="capsule" rgba="0.9 0.7 0.7 0.2" contype="1" conaffinity="0"/>
          <body pos="-0.2 -0.2 0">
            <joint axis="-1 1 0" name="invis_ankle_3" pos="0.0 0.0 0.0" range="-70 -30" type="hinge"/>
            <geom fromto="0.0 0.0 0.0 -0.4 -0.4 0.0" name="invis_third_ankle_geom" size="0.08" type="capsule"
                rgba="1.0 0.4 0.4 0.4" contype="1" conaffinity="0"/>
          </body>
        </body>
      </body>
      <body name="invis_right_back_leg" pos="0 0 0">
        <geom fromto="0.0 0.0 0.0 0.2 -0.2 0.0" name="invis_aux_4_geom" size="0.08" type="capsule" rgba="0.9 0.7 0.7 0.2" contype="1" conaffinity="0"/>
        <body name="invis_aux_4" pos="0.2 -0.2 0">
          <joint axis="0 0 1" name="invis_hip_4" pos="0.0 0.0 0.0" range="-30 30" type="hinge"/>
          <geom fromto="0.0 0.0 0.0 0.2 -0.2 0.0" name="invis_rightback_leg_geom" size="0.08" type="capsule" rgba="0.9 0.7 0.7 0.2" contype="1" conaffinity="0"/>
          <body pos="0.2 -0.2 0">
            <joint axis="1 1 0" name="invis_ankle_4" pos="0.0 0.0 0.0" range="30 70" type="hinge"/>
            <geom fromto="0.0 0.0 0.0 0.4 -0.4 0.0" name="invis_fourth_ankle_geom" size="0.08" type="capsule"
                rgba="1.0 0.4 0.4 0.4" contype="1" conaffinity="0"/>
          </body>
        </body>
      </body>
    </body>
</mujoco>
