<?xml version="1.0" encoding="utf-8"?>
<mujoco>
    <include file="config_pnp.xml"></include>
    <worldbody>
        <include file="sawyer_xyz_base_pnp.xml"></include>
        <body name="wall" pos="0 0.6 0.04">
            <geom type="box" pos="0 0 0" size="0.10 0.015 0.04"
                  rgba=".6 .6 .5 1" contype="15" conaffinity="15" />
        </body>
        <body name="obj" pos="0 0 0.0">
            <joint name="objjoint_y" type="slide" pos="0.0 0.0 0.0" axis="0 1 0" limited='false' damping="0" armature="0"/>
            <joint name="objjoint_z" type="slide" pos="0.0 0.0 0.0" axis="0 0 1" limited='false' damping="0" armature="0"/>
            <!--<inertial pos="0 0 0" mass="0.01" diaginertia="100000 100000 100000"/>-->
            <!--<inertial pos="0 0 0" mass="0.01" diaginertia="100000 100000 100000"/>-->
            <geom name="objbox" type="box" pos="0 0 0"
                size=".025 .015 .015" rgba="0.0 0.0 1.0 1"
                contype="1" conaffinity="1" condim="3" mass="0.01"

                  />
            <body name="obj_T" pos="0 0 0.01">
                <geom name="obj_T_geom" type="box" pos="0 0 0"
                    size=".025 .017 .005" rgba="0.0 0.0 1.0 1"
                    contype="1" conaffinity="1" condim="3"
                />
            </body>

            <site name="obj" pos="0 .0 0" size="0.035" rgba="0.0 0.0 1.0 1"/>
            <!--<site name="obj" pos="0 .0 0" size="0.018 0.018 0.016" type="box" rgba="0.0 1.0 0.0 0.2"/>-->
        </body>

        <body name="obj2" pos="0 0 0.0">
            <joint name="objjoint_y2" type="slide" pos="0.0 0.0 0.0" axis="0 1 0" limited='false' damping="0" armature="0"/>
            <joint name="objjoint_z2" type="slide" pos="0.0 0.0 0.0" axis="0 0 1" limited='false' damping="0" armature="0"/>
            <!--<inertial pos="0 0 0" mass="0.01" diaginertia="100000 100000 100000"/>-->
            <!--<inertial pos="0 0 0" mass="10.0" diaginertia="100000 100000 100000"/>-->
            <geom name="objbox2" type="box" pos="0 0 0"
                size=".025 .015 .015" rgba="1.0 0.0 0.0 1"
                contype="1" conaffinity="1" condim="3" mass="0.01"

                  />
            <body name="obj_T2" pos="0 0 0.01">
                <geom name="obj_T_geom2" type="box" pos="0 0 0"
                    size=".025 .017 .005" rgba="1.0 0.0 0.0 1"
                    contype="1" conaffinity="1" condim="3"
                />
            </body>

           <site name="obj2" pos="0 .0 0" size="0.035" rgba="1.0 0.0 0.0 1"/>
            <!--<site name="obj2" pos="0 .0 0" size="0.018 0.018 0.018" type="box" rgba="0.0 1.0 0.0 0.2"/>-->
        </body>

        <site name="hand-goal-site" pos="0 0 0" size="0.01"
              rgba="1 0.5 0.5 0.5"/>
        <site name="obj-goal-site" pos="0 0 0" size="0.01"
              rgba="0.5 0.5 1 0.5"/>
    </worldbody>
    <actuator>
        <!--<motor gear="100" joint="rc_close"  />-->
        <position ctrllimited="true" ctrlrange="-1 1" joint="rc_close" kp="400"  user="1"/>
        <!--<position ctrllimited="true" ctrlrange="-1 1" joint="rc_close" kp="2000"  user="1"/>-->
    </actuator>
</mujoco>
