<?xml version="1.0" encoding="utf-8"?>
<!-- Same a gym ant but with gear ratio of 30 and sites -->
<mujoco model="ant">
    <!--<body name="s1_torso" pos="-2.25 2.50 0.75">-->
  <body name="s1_torso" pos="-2.25 0.0 0.75">
      <geom name="s1_torso_geom" pos="0 0 0" size="0.25" type="sphere" rgba="1.0 0.2 0.2 1.0"/>
      <joint armature="0" damping="0" limited="false" margin="0.01" name="s1_root" pos="0 0 0" type="free"/>
      <body name="s1_front_left_leg" pos="0 0 0">
        <geom fromto="0.0 0.0 0.0 0.2 0.2 0.0" name="s1_aux_1_geom" size="0.08" type="capsule" rgba="1.0 0.2 0.2 1.0"/>
        <body name="s1_aux_1" pos="0.2 0.2 0">
          <joint axis="0 0 1" name="s1_hip_1" pos="0.0 0.0 0.0" range="-30 30" type="hinge"/>
          <geom fromto="0.0 0.0 0.0 0.2 0.2 0.0" name="s1_left_leg_geom" size="0.08" type="capsule" rgba="1.0 0.2 0.2 1.0"/>
          <body pos="0.2 0.2 0">
            <joint axis="-1 1 0" name="s1_ankle_1" pos="0.0 0.0 0.0" range="30 70" type="hinge"/>
            <geom fromto="0.0 0.0 0.0 0.4 0.4 0.0" name="s1_left_ankle_geom" size="0.08" type="capsule" rgba="1.0 0.2 0.2 1.0"/>
          </body>
        </body>
      </body>
      <body name="s1_front_right_leg" pos="0 0 0">
        <geom fromto="0.0 0.0 0.0 -0.2 0.2 0.0" name="s1_aux_2_geom" size="0.08" type="capsule" rgba="1.0 0.2 0.2 1.0"/>
        <body name="s1_aux_2" pos="-0.2 0.2 0">
          <joint axis="0 0 1" name="s1_hip_2" pos="0.0 0.0 0.0" range="-30 30" type="hinge"/>
          <geom fromto="0.0 0.0 0.0 -0.2 0.2 0.0" name="s1_right_leg_geom" size="0.08" type="capsule" rgba="1.0 0.2 0.2 1.0"/>
          <body pos="-0.2 0.2 0">
            <joint axis="1 1 0" name="s1_ankle_2" pos="0.0 0.0 0.0" range="-70 -30" type="hinge"/>
            <geom fromto="0.0 0.0 0.0 -0.4 0.4 0.0" name="s1_right_ankle_geom" size="0.08" type="capsule" rgba="1.0 0.2 0.2 1.0"/>
          </body>
        </body>
      </body>
      <body name="s1_back_leg" pos="0 0 0">
        <geom fromto="0.0 0.0 0.0 -0.2 -0.2 0.0" name="s1_aux_3_geom" size="0.08" type="capsule" rgba="1.0 0.2 0.2 1.0"/>
        <body name="s1_aux_3" pos="-0.2 -0.2 0">
          <joint axis="0 0 1" name="s1_hip_3" pos="0.0 0.0 0.0" range="-30 30" type="hinge"/>
          <geom fromto="0.0 0.0 0.0 -0.2 -0.2 0.0" name="s1_back_leg_geom" size="0.08" type="capsule" rgba="1.0 0.2 0.2 1.0"/>
          <body pos="-0.2 -0.2 0">
            <joint axis="-1 1 0" name="s1_ankle_3" pos="0.0 0.0 0.0" range="-70 -30" type="hinge"/>
            <geom fromto="0.0 0.0 0.0 -0.4 -0.4 0.0" name="s1_third_ankle_geom" size="0.08" type="capsule"
            rgba="1.0 0.2 0.2 1.0"/>
          </body>
        </body>
      </body>
      <body name="s1_right_back_leg" pos="0 0 0">
        <geom fromto="0.0 0.0 0.0 0.2 -0.2 0.0" name="s1_aux_4_geom" size="0.08" type="capsule" rgba="1.0 0.2 0.2 1.0"/>
        <body name="s1_aux_4" pos="0.2 -0.2 0">
          <joint axis="0 0 1" name="s1_hip_4" pos="0.0 0.0 0.0" range="-30 30" type="hinge"/>
          <geom fromto="0.0 0.0 0.0 0.2 -0.2 0.0" name="s1_rightback_leg_geom" size="0.08" type="capsule" rgba="1.0 0.2 0.2 1.0"/>
          <body pos="0.2 -0.2 0">
            <joint axis="1 1 0" name="s1_ankle_4" pos="0.0 0.0 0.0" range="30 70" type="hinge"/>
            <geom fromto="0.0 0.0 0.0 0.4 -0.4 0.0" name="s1_fourth_ankle_geom" size="0.08" type="capsule"
                rgba="1.0 0.2 0.2 1.0"/>
          </body>
        </body>
      </body>
    </body>
</mujoco>
