<?xml version="1.0" ?>
<robot name="cube.urdf">

  <link name="world"/>

  <link name="baseLink">
    <contact>
      <lateral_friction value="1.0"/>
      <rolling_friction value="0.0"/>
      <contact_cfm value="0.0"/>
      <contact_erp value="1.0"/>
    </contact>
    <inertial>
      <origin rpy="0 0 0" xyz="0.0 0.02 0.0"/>
       <mass value=".1"/>
       <inertia ixx="1" ixy="0" ixz="0" iyy="1" iyz="0" izz="1"/>
    </inertial>
    <visual>
      <origin rpy="0 0 0" xyz="0 0 0"/>
      <geometry>
        <mesh filename="roboverse/envs/assets/objects/duck.obj" scale=".05 .05 .05"/>
      </geometry>
       <material name="yellow">
        <color rgba="1 1 0.4 1"/>
      </material>
    </visual>
    <collision>
      <origin rpy="0 0 0" xyz="0 0 0"/>
      <geometry>
	 	   <mesh filename="roboverse/envs/assets/objects/duck_vhacd.obj" scale=".05 .05 .05"/>
      </geometry>
    </collision>
  </link>

  <joint name="j_lid" type="prismatic">
    <origin rpy="0 0 0" xyz="0 0 0.35"/>
    <parent link="world"/>
    <child link="baseLink"/>
    <axis xyz="0 1 0"/>
    <limit effort="100" lower="0" upper="0.2" velocity="100"/>
  </joint>

</robot>