<?xml version="0.0" ?>
<robot name="bowl.urdf">

  <material name="yellow">
    <color rgba="1 1 0.4 1"/>
  </material>
  <material name="red">
    <color rgba="1 0 0 1"/>
  </material>
  <material name="blue">
    <color rgba=".17 .20 .38 1"/>
  </material>
  <material name="teal">
    <color rgba="0 .5 .5 1"/>
  </material>
  <material name="orange">
    <color rgba=".93 .6 .23 1"/>
  </material>

  <link name="world"/>

  <link name="base">
<!--     <contact>
      <lateral_friction value="1.0"/>
      <rolling_friction value="0.0"/>
      <contact_cfm value="0.0"/>
      <contact_erp value="1.0"/>
    </contact> -->
    <inertial>
      <origin rpy="0 0 0" xyz="0.0 0.0 0.0"/>
       <mass value=".1"/>
       <inertia ixx="1" ixy="0" ixz="0" iyy="1" iyz="0" izz="1"/>
    </inertial>
    <visual>
      <origin rpy="0 0 0" xyz="0 0 0"/>
      <geometry>
        <!-- <box size="1 1 1"/> -->
        <mesh filename="roboverse/envs/assets/objects/bowl/base.dae" scale=".7 .7 .7"/>
      </geometry>
       <material name="teal"/>
    </visual>
    <collision>
      <origin rpy="0 0 0" xyz="0 0 -.3"/>
      <geometry>
	 			<box size="1.2 1.2 .1"/>
      </geometry>
    </collision>
    <collision>
      <!-- right -->
      <origin rpy="0 0 0" xyz="0 -.45 0"/>
      <geometry>
        <box size="1 .05 .5"/>
      </geometry>
    </collision>
    <collision>
      <!-- left -->
      <origin rpy="0 0 0" xyz="0 .45 0"/>
      <geometry>
        <box size="1 .05 .5"/>
      </geometry>
    </collision>
    <collision>
      <!-- front -->
      <origin rpy="0 0 0" xyz=".45 0 0"/>
      <geometry>
        <box size=".05 1 .5"/>
      </geometry>
    </collision>
    <collision>
      <!-- back -->
      <origin rpy="0 0 0" xyz="-.45 0 0"/>
      <geometry>
        <box size=".05 1 .5"/>
      </geometry>
    </collision>
  </link>

  <link name="lid">
    <lateral_friction value="1.0"/>
    <rolling_friction value="0.0"/>
    <contact_cfm value="0.0"/>
    <contact_erp value="1.0"/>
    <inertial>
      <origin rpy="0 0 0" xyz="0.0 0.0 0.0"/>
       <mass value=".25"/>
       <inertia ixx="1" ixy="0" ixz="0" iyy="1" iyz="0" izz="1"/>
    </inertial>
    <visual>
      <origin rpy="0 0 0" xyz="0 0 0"/>
      <geometry>
        <cylinder radius="0.7" length=".05"/>
      </geometry>
       <material name="blue"/>
    </visual>
    <collision>
      <origin rpy="0 0 0" xyz="0 0 0"/>
      <geometry>
        <cylinder radius="0.7" length=".05"/>
      </geometry>
    </collision>
  </link>

  <link name="handle">
    <lateral_friction value="1.0"/>
    <rolling_friction value="0.0"/>
    <contact_cfm value="0.0"/>
    <contact_erp value="1.0"/>
    <inertial>
      <origin rpy="0 0 0" xyz="0.0 0.0 0.0"/>
       <mass value=".1"/>
       <inertia ixx="1" ixy="0" ixz="0" iyy="1" iyz="0" izz="1"/>
    </inertial>
    <visual>
      <origin rpy="0 0 0" xyz="0 0 0"/>
      <geometry>
        <box size="0.5 0.2 .2"/>
      </geometry>
       <material name="orange"/>
    </visual>
    <collision>
      <origin rpy="0 0 0" xyz="0 0 0"/>
      <geometry>
        <box size="0.5 0.2 .2"/>
      </geometry>
    </collision>
  </link>

  <joint name="base_joint" type="fixed">
    <parent link="world"/>
    <child link="base"/>
  </joint>

  <joint name="lid_joint" type="prismatic">
    <origin rpy="0 0 0" xyz="0 0 0.35"/>
    <parent link="base"/>
    <child link="lid"/>
    <axis xyz="0 1 0"/>
    <limit effort="100" lower="0" upper="1" velocity="100"/>
  </joint>

  <joint name="handle_joint" type="fixed">
    <origin rpy="0 0 0" xyz="0 0 0.1"/>
    <parent link="lid"/>
    <child link="handle"/>
  </joint>

</robot>

